Workbook
Name MAPAS: RESULTADO!$F$89:$Q$97
Name TAB: RESULTADO!$E$89:$Q$97

Sheet DADOS DO TIME
C3: POSIÇÃO E ABATES | S3: POSIÇÃO | T3: LBFF 2021 | AA3: LBFF 2021 | AB3: LBFF 2020 | AC3: PERSONALIZADO
C4: MAPAS | D4: BERMUDA | E4: PURGATÓRIO | F4: KALAHARI | G4: NOVA TERRA | H4: ALPINE | I4: SOLARA | J4: BERMUDA | K4: PURGATÓRIO | L4: KALAHARI | M4: NOVA TERRA | N4: ALPINE | O4: SOLARA | S4: 1 | T4: {=IF(T3=AA3,AA4:AA16,IF(T3=AB3,AB4:AB16,IF(T3=AC3,AC4:AC16)))} -> 12 | AA4: 12 | AB4: 20 | AC4: 50
C5: POSIÇÃO | S5: 2 | T5: 9 | AA5: 9 | AB5: 17 | AC5: 9
C6: JOGADORES | D6: ABATES | S6: 3 | T6: 8 | AA6: 8 | AB6: 15 | AC6: 8
C7: JOGADOR 10 | D7: 8 | E7: 4 | F7: 1 | G7: 1 | H7: 1 | I7: 1 | J7: 2 | K7: 1 | L7: 2 | M7: 2 | N7: 50 | O7: 3 | S7: 4 | T7: 7 | AA7: 7 | AB7: 13 | AC7: 7
C8: JOGADOR 2 | D8: 5 | E8: 4 | F8: 5 | G8: 1 | H8: 1 | I8: 1 | J8: 1 | K8: 1 | L8: 2 | M8: 2 | N8: 3 | O8: 3 | S8: 5 | T8: 6 | AA8: 6 | AB8: 12 | AC8: 6
C9: JOGADOR 3 | D9: 1 | E9: 4 | F9: 1 | G9: 1 | H9: 1 | I9: 1 | J9: 1 | K9: 1 | L9: 2 | M9: 2 | N9: 3 | O9: 3 | S9: 6 | T9: 5 | AA9: 5 | AB9: 10 | AC9: 5
C10: JOGADOR 4 | D10: 6 | E10: 6 | F10: 1 | G10: 5 | H10: 6 | I10: 1 | J10: 1 | K10: 1 | L10: 2 | M10: 2 | N10: 3 | O10: 3 | S10: 7 | T10: 4 | AA10: 4 | AB10: 6 | AC10: 4
C11: RESERVA 1 | D11: 5 | E11: 5 | F11: 1 | G11: 1 | H11: 1 | I11: 8 | J11: 1 | K11: 1 | L11: 2 | M11: 2 | N11: 3 | O11: 3 | S11: 8 | T11: 3 | AA11: 3 | AB11: 4 | AC11: 3
C12: UUU | D12: 2 | E12: 7 | F12: 4 | G12: 1 | H12: 1 | I12: 1 | J12: 1 | K12: 1 | L12: 2 | M12: 2 | N12: 3 | O12: 2 | S12: 9 | T12: 2 | AA12: 2 | AB12: 3 | AC12: 2
C13: RESERVA 3 | D13: 2 | E13: 3 | F13: 1 | G13: 1 | H13: 5 | I13: 1 | J13: 1 | K13: 1 | L13: 2 | M13: 2 | N13: 3 | O13: 3 | S13: 10 | T13: 1 | AA13: 1 | AB13: 2 | AC13: 1
C14: RESERVA 4 | D14: 7 | E14: 2 | F14: 1 | G14: 1 | H14: 1 | I14: 1 | J14: 1 | K14: 1 | L14: 54 | M14: 2 | N14: 3 | O14: 3 | S14: 11 | T14: 0 | AA14: 0 | AB14: 1 | AC14: 0
C15: TOTAL | D15: =IFERROR(VLOOKUP(D5,S4:T15,2,0),0)+(D7+D8+D9+D10+D11+D12+D13+D14)*T16 -> 36 | E15: =IFERROR(VLOOKUP(E5,S4:T15,2,0),0)+(E7+E8+E9+E10+E11+E12+E13+E14)*T16 -> 35 | F15: =IFERROR(VLOOKUP(F5,S4:T15,2,0),0)+(F7+F8+F9+F10+F11+F12+F13+F14)*T16 -> 15 | G15: =IFERROR(VLOOKUP(G5,S4:T15,2,0),0)+(G7+G8+G9+G10+G11+G12+G13+G14)*T16 -> 12 | H15: =IFERROR(VLOOKUP(H5,S4:T15,2,0),0)+(H7+H8+H9+H10+H11+H12+H13+H14)*T16 -> 17 | I15: =IFERROR(VLOOKUP(I5,S4:T15,2,0),0)+(I7+I8+I9+I10+I11+I12+I13+I14)*T16 -> 15 | J15: =IFERROR(VLOOKUP(J5,S4:T15,2,0),0)+(J7+J8+J9+J10+J11+J12+J13+J14)*T16 -> 9 | K15: =IFERROR(VLOOKUP(K5,S4:T15,2,0),0)+(K7+K8+K9+K10+K11+K12+K13+K14)*T16 -> 8 | L15: =IFERROR(VLOOKUP(L5,S4:T15,2,0),0)+(L7+L8+L9+L10+L11+L12+L13+L14)*T16 -> 68 | M15: =IFERROR(VLOOKUP(M5,S4:T15,2,0),0)+(M7+M8+M9+M10+M11+M12+M13+M14)*T16 -> 16 | N15: =IFERROR(VLOOKUP(N5,S4:T15,2,0),0)+(N7+N8+N9+N10+N11+N12+N13+N14)*T16 -> 71 | O15: =IFERROR(VLOOKUP(O5,S4:T15,2,0),0)+(O7+O8+O9+O10+O11+O12+O13+O14)*T16 -> 23 | S15: 12 | T15: 0 | AA15: 0 | AB15: 0 | AC15: 0
S16: KILL | T16: 1 | AA16: 1 | AB16: 2 | AC16: 1
C17: DANOS
C18: JOGADORES | D18: =D4 -> BERMUDA | E18: =E4 -> PURGATÓRIO | F18: =F4 -> KALAHARI | G18: =G4 -> NOVA TERRA | H18: =H4 -> ALPINE | I18: =I4 -> SOLARA | J18: =J4 -> BERMUDA | K18: =K4 -> PURGATÓRIO | ... O18: =O4 -> SOLARA
C19: =C7 -> JOGADOR 10 | D19: 2 | O19: 6 | S19: MAPAS DO DIA
C20: =C8 -> JOGADOR 2 | S20: BERMUDA
C21: =C9 -> JOGADOR 3 | S21: PURGATÓRIO
C22: =C10 -> JOGADOR 4 | S22: KALAHARI
C23: =C11 -> RESERVA 1 | O23: 22 | S23: NOVA TERRA
C24: =C12 -> UUU | S24: ALPINE
C25: =C13 -> RESERVA 3 | S25: SOLARA
C26: =C14 -> RESERVA 4
C28: TEMPO DE SOBREVIVÊNCIA
C29: JOGADORES | D29: =D4 -> BERMUDA | E29: =E4 -> PURGATÓRIO | F29: =F4 -> KALAHARI | G29: =G4 -> NOVA TERRA | H29: =H4 -> ALPINE | I29: =I4 -> SOLARA | J29: =J4 -> BERMUDA | K29: =K4 -> PURGATÓRIO | ... O29: =O4 -> SOLARA
C30: =C7 -> JOGADOR 10
C31: =C8 -> JOGADOR 2
C32: =C9 -> JOGADOR 3
C33: =C10 -> JOGADOR 4
C34: =C11 -> RESERVA 1
C35: =C12 -> UUU
C36: =C13 -> RESERVA 3
C37: =C14 -> RESERVA 4
C39: ASSISTÊNCIAS
C40: JOGADORES | D40: =D4 -> BERMUDA | E40: =E4 -> PURGATÓRIO | F40: =F4 -> KALAHARI | G40: =G4 -> NOVA TERRA | H40: =H4 -> ALPINE | I40: =I4 -> SOLARA | J40: =J4 -> BERMUDA | K40: =K4 -> PURGATÓRIO | ... O40: =O4 -> SOLARA
C41: =C7 -> JOGADOR 10 | D41: 4 | E41: 7 | F41: 5 | H41: 5 | J41: 4 | K41: 2 | M41: 5 | O41: 5
C42: =C8 -> JOGADOR 2 | D42: 4
C43: =C9 -> JOGADOR 3 | D43: 3 | J43: 5
C44: =C10 -> JOGADOR 4 | D44: 2 | G44: 5
...

Sheet RESULTADO
C3: JOGADORES | D3: DESEMPENHO DOS JOGADORES
D4: TOTAL DE ABATES | E4: TAXA DE ABATES | F4: TOTAL DE DANO | G4: TOTAL DE ASSISTÊNCIAS | H4: MÉDIA DE ASSISTÊNCIAS | I4: TEMPO DE SOBREVIVÊNCIA | J4: MÉDIA DE SOBREVIVÊNCIA | K4: TOTAL DE QUEDAS
C5: ='DADOS DO TIME'!C7 -> JOGADOR 10 | D5: =SUM('DADOS DO TIME'!D7:O7) -> 76 | E5: =IFERROR(D5/K5,0) -> 6.3333333 | F5: =SUM('DADOS DO TIME'!D19:O19) -> 8 | G5: =SUM('DADOS DO TIME'!D41:O41) -> 37 | H5: =IFERROR(AVERAGE('DADOS DO TIME'!D41:O41),0) -> 4.625 | I5: =SUM('DADOS DO TIME'!D30:O30) -> 0 | J5: =IFERROR(AVERAGE('DADOS DO TIME'!D30:O30),0) -> 0 | K5: =COUNT('DADOS DO TIME'!D7:O7) -> 12
C6: ='DADOS DO TIME'!C8 -> JOGADOR 2 | D6: =SUM('DADOS DO TIME'!D8:O8) -> 29 | E6: =IFERROR(D6/K6,0) -> 2.4166667 | F6: =SUM('DADOS DO TIME'!D20:O20) -> 0 | G6: =SUM('DADOS DO TIME'!D42:O42) -> 4 | H6: =IFERROR(AVERAGE('DADOS DO TIME'!D42:O42),0) -> 4 | I6: =SUM('DADOS DO TIME'!D31:O31) -> 0 | J6: =IFERROR(AVERAGE('DADOS DO TIME'!D31:O31),0) -> 0 | K6: =COUNT('DADOS DO TIME'!D8:O8) -> 12
C7: ='DADOS DO TIME'!C9 -> JOGADOR 3 | D7: =SUM('DADOS DO TIME'!D9:O9) -> 21 | E7: =IFERROR(D7/K7,0) -> 1.75 | F7: =SUM('DADOS DO TIME'!D21:O21) -> 0 | G7: =SUM('DADOS DO TIME'!D43:O43) -> 8 | H7: =IFERROR(AVERAGE('DADOS DO TIME'!D43:O43),0) -> 4 | I7: =SUM('DADOS DO TIME'!D32:O32) -> 0 | J7: =IFERROR(AVERAGE('DADOS DO TIME'!D32:O32),0) -> 0 | K7: =COUNT('DADOS DO TIME'!D9:O9) -> 12
C8: ='DADOS DO TIME'!C10 -> JOGADOR 4 | D8: =SUM('DADOS DO TIME'!D10:O10) -> 37 | E8: =IFERROR(D8/K8,0) -> 3.0833333 | F8: =SUM('DADOS DO TIME'!D22:O22) -> 0 | G8: =SUM('DADOS DO TIME'!D44:O44) -> 7 | H8: =IFERROR(AVERAGE('DADOS DO TIME'!D44:O44),0) -> 3.5 | I8: =SUM('DADOS DO TIME'!D33:O33) -> 0 | J8: =IFERROR(AVERAGE('DADOS DO TIME'!D33:O33),0) -> 0 | K8: =COUNT('DADOS DO TIME'!D10:O10) -> 12
C9: ='DADOS DO TIME'!C11 -> RESERVA 1 | D9: =SUM('DADOS DO TIME'!D11:O11) -> 33 | E9: =IFERROR(D9/K9,0) -> 2.75 | F9: =SUM('DADOS DO TIME'!D23:O23) -> 22 | G9: =SUM('DADOS DO TIME'!D45:O45) -> 25 | H9: =IFERROR(AVERAGE('DADOS DO TIME'!D45:O45),0) -> 5 | I9: =SUM('DADOS DO TIME'!D34:O34) -> 0 | J9: =IFERROR(AVERAGE('DADOS DO TIME'!D34:O34),0) -> 0 | K9: =COUNT('DADOS DO TIME'!D11:O11) -> 12
C10: ='DADOS DO TIME'!C12 -> UUU | D10: =SUM('DADOS DO TIME'!D12:O12) -> 27 | E10: =IFERROR(D10/K10,0) -> 2.25 | F10: =SUM('DADOS DO TIME'!D24:O24) -> 0 | G10: =SUM('DADOS DO TIME'!D46:O46) -> 12 | H10: =IFERROR(AVERAGE('DADOS DO TIME'!D46:O46),0) -> 4 | I10: =SUM('DADOS DO TIME'!D35:O35) -> 0 | J10: =IFERROR(AVERAGE('DADOS DO TIME'!D35:O35),0) -> 0 | K10: =COUNT('DADOS DO TIME'!D12:O12) -> 12
C11: ='DADOS DO TIME'!C13 -> RESERVA 3 | D11: =SUM('DADOS DO TIME'!D13:O13) -> 25 | E11: =IFERROR(D11/K11,0) -> 2.0833333 | F11: =SUM('DADOS DO TIME'!D25:O25) -> 0 | G11: =SUM('DADOS DO TIME'!D47:O47) -> 2 | H11: =IFERROR(AVERAGE('DADOS DO TIME'!D47:O47),0) -> 2 | I11: =SUM('DADOS DO TIME'!D36:O36) -> 0 | J11: =IFERROR(AVERAGE('DADOS DO TIME'!D36:O36),0) -> 0 | K11: =COUNT('DADOS DO TIME'!D13:O13) -> 12
C12: ='DADOS DO TIME'!C14 -> RESERVA 4 | D12: =SUM('DADOS DO TIME'!D14:O14) -> 77 | E12: =IFERROR(D12/K12,0) -> 6.4166667 | F12: =SUM('DADOS DO TIME'!D26:O26) -> 0 | G12: =SUM('DADOS DO TIME'!D48:O48) -> 10 | H12: =IFERROR(AVERAGE('DADOS DO TIME'!D48:O48),0) -> 5 | I12: =SUM('DADOS DO TIME'!D37:O37) -> 0 | J12: =IFERROR(AVERAGE('DADOS DO TIME'!D37:O37),0) -> 0 | K12: =COUNT('DADOS DO TIME'!D14:O14) -> 12
T16: DE | U16: =COUNTA('DADOS DO TIME'!D5:O5) -> 0 | V16: PARTIDA(S) JOGADA(S) O TIME ACUMULOU UM TOTAL DE | AA16: =SUM('DADOS DO TIME'!D7:O14) -> 325 | AB16: KILLS, | AC16: E FICOU ENTRE OS 3 PRIMEIROS | AF16: =COUNTIF('DADOS DO TIME'!D5:O5,"<4") -> 0 | AG16: VEZ(ES)!
C18: CLASSIFICAÇÃO DO TIME
C19: QUEDAS | D19: MAPAS | E19: KILLS | F19: PONTOS
C20: 1ª | D20: ='DADOS DO TIME'!D4 -> BERMUDA | E20: =SUM('DADOS DO TIME'!D7:D14) -> 36 | F20: ='DADOS DO TIME'!D15 -> 36
C21: 2ª | D21: ='DADOS DO TIME'!E4 -> PURGATÓRIO | E21: =SUM('DADOS DO TIME'!E7:E14) -> 35 | F21: ='DADOS DO TIME'!E15 -> 35
C22: 3ª | D22: ='DADOS DO TIME'!F4 -> KALAHARI | E22: =SUM('DADOS DO TIME'!F7:F14) -> 15 | F22: ='DADOS DO TIME'!F15 -> 15
C23: 4ª | D23: ='DADOS DO TIME'!G4 -> NOVA TERRA | E23: =SUM('DADOS DO TIME'!G7:G14) -> 12 | F23: ='DADOS DO TIME'!G15 -> 12
C24: 5ª | D24: ='DADOS DO TIME'!H4 -> ALPINE | E24: =SUM('DADOS DO TIME'!H7:H14) -> 17 | F24: ='DADOS DO TIME'!H15 -> 17
C25: 6ª | D25: ='DADOS DO TIME'!I4 -> SOLARA | E25: =SUM('DADOS DO TIME'!I7:I14) -> 15 | F25: ='DADOS DO TIME'!I15 -> 15 | T25: =_xlfn.CONCAT(T16," ",U16," ",V16," ",AA16," ",AB16," ",AC16," ",AJ23," ",AF16," ",AG16) -> DE 0 PARTIDA(S) JOGADA(S) O TIME ACUMULOU UM TOTAL DE 325 KILLS, E FICOU ENTRE OS 3 PRIMEIROS 0 VEZ(ES)!
C26: 7ª | D26: ='DADOS DO TIME'!J4 -> BERMUDA | E26: =SUM('DADOS DO TIME'!J7:J14) -> 9 | F26: ='DADOS DO TIME'!J15 -> 9
C27: 8ª | D27: ='DADOS DO TIME'!K4 -> PURGATÓRIO | E27: =SUM('DADOS DO TIME'!K7:K14) -> 8 | F27: ='DADOS DO TIME'!K15 -> 8
C28: 9ª | D28: ='DADOS DO TIME'!L4 -> KALAHARI | E28: =SUM('DADOS DO TIME'!L7:L14) -> 68 | F28: ='DADOS DO TIME'!L15 -> 68
C29: 10ª | D29: ='DADOS DO TIME'!M4 -> NOVA TERRA | E29: =SUM('DADOS DO TIME'!M7:M14) -> 16 | F29: ='DADOS DO TIME'!M15 -> 16
C30: 11ª | D30: ='DADOS DO TIME'!N4 -> ALPINE | E30: =SUM('DADOS DO TIME'!N7:N14) -> 71 | F30: ='DADOS DO TIME'!N15 -> 71
C31: 12ª | D31: ='DADOS DO TIME'!O4 -> SOLARA | E31: =SUM('DADOS DO TIME'!O7:O14) -> 23 | F31: ='DADOS DO TIME'!O15 -> 23 | U31: MAPAS | V31: Q
C32: TOTAL | E32: =SUM(E20:E31) -> 325 | F32: ='DADOS DO TIME'!D15+'DADOS DO TIME'!E15+'DADOS DO TIME'!F15+'DADOS DO TIME'!G15+'DADOS DO TIME'!H15+'DADOS DO TIME'!I15+'DADOS DO TIME'!J15+'DADOS DO TIME'!K15+'DADOS DO TIME'!N15+'DADOS DO TIME'!O15 -> 241 | U32: BERMUDA | V32: =COUNTIF('DADOS DO TIME'!D4:O4,RESULTADO!U32) -> 2
U33: PURGATÓRIO | V33: =COUNTIF('DADOS DO TIME'!D4:O4,RESULTADO!U33) -> 2
U34: KALAHARI | V34: =COUNTIF('DADOS DO TIME'!D4:O4,RESULTADO!U34) -> 2
U35: NOVA TERRA | V35: =COUNTIF('DADOS DO TIME'!D4:O4,RESULTADO!U35) -> 2
U36: ALPINE | V36: =COUNTIF('DADOS DO TIME'!D4:O4,RESULTADO!U36) -> 2
U37: SOLARA | V37: =COUNTIF('DADOS DO TIME'!D4:O4,RESULTADO!U37) -> 2
U42: OS 4 PLAYERS COM MAIS ABATES NO MAPA | W42: SÃO: | X42: =G49 -> BERMUDA | AD42: =E302 -> JOGADOR 10 | AE42: , | AF42: =E303 -> RESERVA 4 | AG42: , | AH42: =E304 -> JOGADOR 4 | AI42: E | AJ42: =E305 -> JOGADOR 2 | AK42: !
U44: =_xlfn.CONCAT(U42," ",G49," ",W42," ",AD42,AE42," ",AF42,AG42," ",AH42," ",AI42," ",AJ42,AK42) -> OS 4 PLAYERS COM MAIS ABATES NO MAPA BERMUDA SÃO: JOGADOR 10, RESERVA 4, JOGADOR 4 E JOGADOR 2!
U48: OS 4 PLAYERS COM MELHOR MÉDIA DE ASSISTÊNCIA NO MAPA | AA48: =H302 -> JOGADOR 10 | AB48: , | AC48: =H303 -> JOGADOR 3 | AD48: , | AE48: =H304 -> RESERVA 1 | AF48: E | AH48: =H305 -> JOGADOR 2 | AI48: !
G49: BERMUDA | AD49: ,
U50: =_xlfn.CONCAT(U48," ",G49," ",X51," ",AA48,AB48," ",AC48,AD48," ",AE48," ",AF48," ",AH48,AI48) -> OS 4 PLAYERS COM MELHOR MÉDIA DE ASSISTÊNCIA NO MAPA BERMUDA SÃO: JOGADOR 10, JOGADOR 3, RESERVA 1 E JOGADOR 2!
X51: SÃO:
V54: FORMULARIO
V55: 2
AE86: 1
...

Sheet RESULTADO DE TODOS OS TREINOS
C3: DESEMPENHO DO TIME | TODOS OS TREINOS DO DIA
C4: TREINOS/ EVENTOS | D4: QUEDAS | E4: KILLS | F4: TAXA DE ABATES | G4: PONTOS
F5: =IFERROR(E5/D5,0) -> 0
F6: =IFERROR(E6/D6,0) -> 0
F7: =IFERROR(E7/D7,0) -> 0
F8: =IFERROR(E8/D8,0) -> 0
F9: =IFERROR(E9/D9,0) -> 0
F10: =IFERROR(E10/D10,0) -> 0 | P10: EM | Q10: =COUNTA(C5:C16) -> 0 | R10: EVENTOS JOGADOS O TIME FEZ | S10: KILLS | T10: E | U10: PONTOS, | V10: RESULTANDO EM UMA TAXA DE | W10: % | X10: DE ABATES!
F11: =IFERROR(E11/D11,0) -> 0
F12: =IFERROR(E12/D12,0) -> 0
F13: =IFERROR(E13/D13,0) -> 0
F14: =IFERROR(E14/D14,0) -> 0
F15: =IFERROR(E15/D15,0) -> 0 | Q15: =ROUND(F17,1) -> 0
F16: =IFERROR(E16/D16,0) -> 0
C17: TOTAL | D17: =SUM(D5:D16) -> 0 | E17: =SUM(E5:E16) -> 0 | F17: =SUM(F5:F16) -> 0 | G17: =SUM(G5:G16) -> 0
P23: =_xlfn.CONCAT(P10," ",Q10," ",R10," ",E17," ",S10," ",T10," ",G17," ",U10," ",V10," ",Q15,"",W10," ",X10) -> EM 0 EVENTOS JOGADOS O TIME FEZ 0 KILLS E 0 PONTOS, RESULTANDO EM UMA TAXA DE 0% DE ABATES!
I31: =S19 -> 0
